Workbook

Sheet MAIN
L1: =XLE_IYE!A1 -> date | M1: XLE_IYE | N1: XLF_IYF | O1: XLK_IYW | P1: XLU_IDU | Q1: IYJ_XLI | R1: IYK_XLP | S1: SUM | T1: CUM SUM | X1: XLRE_IYR | Y1: IYH_XLV
L2: =XLE_IYE!A2 -> 46024
L3: =XLE_IYE!A3 -> 46027 | M3: =SUM(M22:M156) -> 0.014788768 | N3: =SUM(N22:N156) -> 0.048495725 | O3: =SUM(O22:O156) -> 0.068169528 | P3: =SUM(P22:P156) -> 0.02097267 | Q3: =SUM(Q22:Q156) -> 0.053815852 | R3: =SUM(R22:R156) -> 0.061563535 | S3: =SUM(S22:S156) -> 0.26780608 | T3: =T156 -> 0.26780608 | X3: =SUM(X22:X156) -> -3.9108352e-05 | Y3: =SUM(Y22:Y156) -> 0.0052519152
C4: XLE | D4: IYE | E4: -20 | F4: 20 | H4: =XLE_IYE!BC$1 -> 0.014788768 | I4: =XLE_IYE!BB$11 -> 2.4557288 | L4: =XLE_IYE!A4 -> 46028
C5: XLF | D5: IYF | E5: -40 | F5: 40 | H5: =XLF_IYF!BC$1 -> 0.048495725 | I5: =XLF_IYF!BB$11 -> 3.6284014 | L5: =XLE_IYE!A5 -> 46029
C6: XLK | D6: IYW | E6: -50 | F6: 50 | H6: =XLK_IYW!BC$1 -> 0.068169528 | I6: =XLK_IYW!BB$11 -> 2.157143 | L6: =XLE_IYE!A6 -> 46030 | S6: =AVERAGE(S22:S156) -> 0.0019837487
C7: XLU | D7: IDU | E7: -20 | F7: 20 | H7: =XLU_IDU!BC$1 -> 0.02097267 | I7: =XLU_IDU!BB$11 -> 2.2757341 | L7: =XLE_IYE!A7 -> 46031 | S7: =STDEV(S22:S156) -> 0.0066072992
C8: IYJ | D8: XLI | E8: -50 | F8: 40 | H8: =IYJ_XLI!BC$1 -> 0.053815852 | I8: =IYJ_XLI!BB$11 -> 2.147851 | L8: =XLE_IYE!A8 -> 46034 | S8: =SQRT(252)*S6/S7 -> 4.7660979
C9: IYK | D9: XLP | E9: -30 | F9: 30 | H9: =IYK_XLP!BC$1 -> 0.061563535 | I9: =IYK_XLP!BB$11 -> 2.1107699 | L9: =XLE_IYE!A9 -> 46035
L10: =XLE_IYE!A10 -> 46036
L11: =XLE_IYE!A11 -> 46037
L12: =XLE_IYE!A12 -> 46038
L13: =XLE_IYE!A13 -> 46042
L14: =XLE_IYE!A14 -> 46043
L15: =XLE_IYE!A15 -> 46044
L16: =XLE_IYE!A16 -> 46045
L17: =XLE_IYE!A17 -> 46048
L18: =XLE_IYE!A18 -> 46049
L19: =XLE_IYE!A19 -> 46050
L20: =XLE_IYE!A20 -> 46051
C21: IYH | D21: XLV | E21: -30 | F21: 20 | H21: =IYH_XLV!BC$1 -> 0.0052519152 | I21: =IYH_XLV!BB$11 -> 0.48105163 | L21: =XLE_IYE!A21 -> 46052
C22: XLRE | D22: IYR | E22: -30 | F22: 30 | G22: 10 | H22: =XLRE_IYR!BC$1 -> -3.9108352e-05 | I22: =XLRE_IYR!BB$11 -> -0.0043271506 | L22: =XLE_IYE!A22 -> 46055 | M22: =XLE_IYE!BB22 -> 0 | N22: =XLF_IYF!BB22 -> 0 | O22: =XLK_IYW!BB22 -> 0 | P22: =XLU_IDU!BB22 -> 0 | Q22: =IYJ_XLI!BB22 -> 0 | R22: =IYK_XLP!BB22 -> 0 | S22: =SUM(M22:R22) -> 0 | T22: =+T21+S22 -> 0 | X22: =XLRE_IYR!BB22 -> 0 | Y22: =IYH_XLV!BB22 -> 0
L23: =XLE_IYE!A23 -> 46056 | M23: =XLE_IYE!BB23 -> 0 | N23: =XLF_IYF!BB23 -> 0 | O23: =XLK_IYW!BB23 -> 0 | P23: =XLU_IDU!BB23 -> 0 | Q23: =IYJ_XLI!BB23 -> -0.0071652214 | R23: =IYK_XLP!BB23 -> 0 | S23: =SUM(M23:R23) -> -0.0071652214 | T23: =+T22+S23 -> -0.0071652214 | X23: =XLRE_IYR!BB23 -> 0.0012507047 | Y23: =IYH_XLV!BB23 -> 0.00025655612
L24: =XLE_IYE!A24 -> 46057 | M24: =XLE_IYE!BB24 -> 0 | N24: =XLF_IYF!BB24 -> 0 | O24: =XLK_IYW!BB24 -> 0.0047527887 | P24: =XLU_IDU!BB24 -> 0 | Q24: =IYJ_XLI!BB24 -> 0.0034611706 | R24: =IYK_XLP!BB24 -> 0 | S24: =SUM(M24:R24) -> 0.0082139593 | T24: =+T23+S24 -> 0.001048738 | X24: =XLRE_IYR!BB24 -> -0.0015876714 | Y24: =IYH_XLV!BB24 -> 0.0012322882
L25: =XLE_IYE!A25 -> 46058 | M25: =XLE_IYE!BB25 -> 0 | N25: =XLF_IYF!BB25 -> 0 | O25: =XLK_IYW!BB25 -> 0 | P25: =XLU_IDU!BB25 -> 0 | Q25: =IYJ_XLI!BB25 -> -0.0010413335 | R25: =IYK_XLP!BB25 -> 0.015411711 | S25: =SUM(M25:R25) -> 0.014370378 | T25: =+T24+S25 -> 0.015419116 | X25: =XLRE_IYR!BB25 -> 0.003277245 | Y25: =IYH_XLV!BB25 -> -0.0050947973
L26: =XLE_IYE!A26 -> 46059 | M26: =XLE_IYE!BB26 -> 0 | N26: =XLF_IYF!BB26 -> 0 | O26: =XLK_IYW!BB26 -> 0 | P26: =XLU_IDU!BB26 -> 0 | Q26: =IYJ_XLI!BB26 -> -0.0028193601 | R26: =IYK_XLP!BB26 -> 0.0033766826 | S26: =SUM(M26:R26) -> 0.00055732247 | T26: =+T25+S26 -> 0.015976438 | X26: =XLRE_IYR!BB26 -> 0 | Y26: =IYH_XLV!BB26 -> -0.00028633555
L27: =XLE_IYE!A27 -> 46062 | M27: =XLE_IYE!BB27 -> 0.00067232701 | N27: =XLF_IYF!BB27 -> 0 | O27: =XLK_IYW!BB27 -> -0.0010875915 | P27: =XLU_IDU!BB27 -> 0 | Q27: =IYJ_XLI!BB27 -> -0.0031230012 | R27: =IYK_XLP!BB27 -> 0.00099781824 | S27: =SUM(M27:R27) -> -0.0025404474 | T27: =+T26+S27 -> 0.013435991 | X27: =XLRE_IYR!BB27 -> 0 | Y27: =IYH_XLV!BB27 -> -0.00045251554
L28: =XLE_IYE!A28 -> 46063 | M28: =XLE_IYE!BB28 -> 0.00023681535 | N28: =XLF_IYF!BB28 -> 0.0041890824 | O28: =XLK_IYW!BB28 -> 0.00043843586 | P28: =XLU_IDU!BB28 -> 0.0013642812 | Q28: =IYJ_XLI!BB28 -> 0.0032141925 | R28: =IYK_XLP!BB28 -> -0.002268797 | S28: =SUM(M28:R28) -> 0.0071740104 | T28: =+T27+S28 -> 0.020610001 | X28: =XLRE_IYR!BB28 -> -0.0011004674 | Y28: =IYH_XLV!BB28 -> 0.0011289511
L29: =XLE_IYE!A29 -> 46064 | M29: =XLE_IYE!BB29 -> -0.00085988862 | N29: =XLF_IYF!BB29 -> 0 | O29: =XLK_IYW!BB29 -> -0.0019696631 | P29: =XLU_IDU!BB29 -> 0 | Q29: =IYJ_XLI!BB29 -> -0.0037807917 | R29: =IYK_XLP!BB29 -> 0.00038170078 | S29: =SUM(M29:R29) -> -0.0062286427 | T29: =+T28+S29 -> 0.014381359 | X29: =XLRE_IYR!BB29 -> -0.0030002883 | Y29: =IYH_XLV!BB29 -> -0.00098761185
L30: =XLE_IYE!A30 -> 46065 | M30: =XLE_IYE!BB30 -> -0.00059297517 | N30: =XLF_IYF!BB30 -> 0 | O30: =XLK_IYW!BB30 -> 0.002264201 | P30: =XLU_IDU!BB30 -> 0.0023315212 | Q30: =IYJ_XLI!BB30 -> -0.0023494402 | R30: =IYK_XLP!BB30 -> 0.0055542212 | S30: =SUM(M30:R30) -> 0.007207528 | T30: =+T29+S30 -> 0.021588887 | X30: =XLRE_IYR!BB30 -> -0.0022408514 | Y30: =IYH_XLV!BB30 -> -0.00054727686
L31: =XLE_IYE!A31 -> 46066 | M31: =XLE_IYE!BB31 -> 0.00068716913 | N31: =XLF_IYF!BB31 -> 0 | O31: =XLK_IYW!BB31 -> -0.0038222324 | P31: =XLU_IDU!BB31 -> -0.0014461983 | Q31: =IYJ_XLI!BB31 -> -0.0037893791 | R31: =IYK_XLP!BB31 -> 0 | S31: =SUM(M31:R31) -> -0.0083706406 | T31: =+T30+S31 -> 0.013218246 | X31: =XLRE_IYR!BB31 -> -0.0010267439 | Y31: =IYH_XLV!BB31 -> -0.00055949053
L32: =XLE_IYE!A32 -> 46070 | M32: =XLE_IYE!BB32 -> 0.00024269627 | N32: =XLF_IYF!BB32 -> 0.0024690391 | O32: =XLK_IYW!BB32 -> 0.00025845041 | P32: =XLU_IDU!BB32 -> -0.00047750645 | Q32: =IYJ_XLI!BB32 -> -0.00095824828 | R32: =IYK_XLP!BB32 -> 0.0049341894 | S32: =SUM(M32:R32) -> 0.0064686205 | T32: =+T31+S32 -> 0.019686867 | X32: =XLRE_IYR!BB32 -> -0.00023433219 | Y32: =IYH_XLV!BB32 -> 0.0012959705
L33: =XLE_IYE!A33 -> 46071 | M33: =XLE_IYE!BB33 -> 0.00037563386 | N33: =XLF_IYF!BB33 -> 0 | O33: =XLK_IYW!BB33 -> 0.00024488315 | P33: =XLU_IDU!BB33 -> 0.00094566545 | Q33: =IYJ_XLI!BB33 -> 0.0027840466 | R33: =IYK_XLP!BB33 -> 0 | S33: =SUM(M33:R33) -> 0.004350229 | T33: =+T32+S33 -> 0.024037096 | X33: =XLRE_IYR!BB33 -> 0.0015909785 | Y33: =IYH_XLV!BB33 -> 7.1914822e-05
L34: =XLE_IYE!A34 -> 46072 | M34: =XLE_IYE!BB34 -> -0.00056223748 | N34: =XLF_IYF!BB34 -> -0.00010035363 | O34: =XLK_IYW!BB34 -> 0.00060644976 | P34: =XLU_IDU!BB34 -> -0.00074436593 | Q34: =IYJ_XLI!BB34 -> -0.0045399767 | R34: =IYK_XLP!BB34 -> 0 | S34: =SUM(M34:R34) -> -0.005340484 | T34: =+T33+S34 -> 0.018696612 | X34: =XLRE_IYR!BB34 -> 0.0016647663 | Y34: =IYH_XLV!BB34 -> 0.00093164059
... L156: =XLE_IYE!A156 -> 46248 | M156: =XLE_IYE!BB156 -> 0 | N156: =XLF_IYF!BB156 -> 0 | O156: =XLK_IYW!BB156 -> -0.00026525902 | P156: =XLU_IDU!BB156 -> 0.00014030999 | Q156: =IYJ_XLI!BB156 -> 0 | R156: =IYK_XLP!BB156 -> 0.0044474506 | S156: =SUM(M156:R156) -> 0.0043225016 | T156: =+T155+S156 -> 0.26780608 | X156: =XLRE_IYR!BB156 -> -0.0016995207 | Y156: =IYH_XLV!BB156 -> 0.00047346538

Sheet XLE_IYE
A1: date | B1: XLE | C1: IYE | D1: IYE/XLE | E1: IYE/XLE avg | F1: IYE/XLE 10 dma | G1: IYE/XLE 20 dma | H1: XLE avg | I1: XLE 10 dma | J1: XLE 20 dma | K1: avg diff | L1: 10 dma diff | M1: 20 dma diff | N1: XLE div | O1: IYE div | P1: XLE* | Q1: IYE* | R1: IYE*/XLE* | S1: IYE*/XLE* avg | T1: IYE*/XLE* 10 dma | U1: IYE*/XLE* 20 dma | V1: XLE* avg | W1: XLE* 10 dma | X1: XLE* 20 dma | Y1: avg diff* | Z1: 10 dma diff* | AA1: 20 dma diff* | AC1: =_xlfn.CONCAT(B1," rtn") -> XLE rtn | AD1: =_xlfn.CONCAT(C1," rtn") -> IYE rtn | AF1: signal | AG1: -0.002 | AH1: under | AI1: over | AJ1: yday | AK1: position | AO1: =AO156 -> 0.0070471859 | AQ1: signal | AR1: 0.002 | AS1: over | AT1: under | AU1: yday | AV1: position | AZ1: =AZ156 -> 0.0077415819 | BC1: =BC156 -> 0.014788768
A2: 46024 | B2: 45.65 | C2: 48.55 | D2: 1.0635268 | E2: 1.0597117 | N2: 0 | O2: 0 | P2: 45.65 | Q2: 48.55 | R2: 1.0635268 | S2: 1.0599915 | AG2: 0 | AR2: 0
A3: 46027 | B3: 46.89 | C3: 49.73 | D3: 1.0605673 | E3: 1.0597117 | H3: 49.68988 | K3: 0.00080708395 | N3: 0 | O3: 0 | P3: 46.89 | Q3: 49.73 | R3: 1.0605673 | S3: 1.0599915 | V3: 49.703003 | Y3: 0.00054302347 | AC3: =LN(B3/B2) -> 0.026800826 | AD3: =LN(C3/C2) -> 0.024014178
A4: 46028 | B4: 45.64 | C4: 48.44 | D4: 1.0613497 | E4: 1.0597117 | H4: 48.36524 | K4: 0.001544538 | N4: 0 | O4: 0 | P4: 45.64 | Q4: 48.44 | R4: 1.0613497 | S4: 1.0599915 | V4: 48.378013 | Y4: 0.0012804775 | AC4: =LN(B4/B3) -> -0.027019908 | AD4: =LN(C4/C3) -> -0.026282454
A5: 46029 | B5: 45.13 | C5: 47.87 | D5: 1.0607135 | E5: 1.0597117 | H5: 47.824787 | K5: 0.00094493389 | N5: 0 | O5: 0 | P5: 45.13 | Q5: 47.87 | R5: 1.0607135 | S5: 1.0599915 | V5: 47.837418 | Y5: 0.00068087341 | AC5: =LN(B5/B4) -> -0.011237311 | AD5: =LN(C5/C4) -> -0.011836915
A6: 46030 | B6: 46.55 | C6: 49.29 | D6: 1.0588614 | E6: 1.0597117 | H6: 49.329578 | K6: -0.00080263869 | N6: 0 | O6: 0 | P6: 46.55 | Q6: 49.29 | R6: 1.0588614 | S6: 1.0599915 | V6: 49.342606 | Y6: -0.0010666992 | AC6: =LN(B6/B5) -> 0.03097979 | AD6: =LN(C6/C5) -> 0.029232217
A7: 46031 | B7: 46.67 | C7: 49.39 | D7: 1.0582816 | E7: 1.0597117 | H7: 49.456743 | K7: -0.0013504411 | N7: 0 | O7: 0 | P7: 46.67 | Q7: 49.39 | R7: 1.0582816 | S7: 1.0599915 | V7: 49.469805 | Y7: -0.0016145016 | AC7: =LN(B7/B6) -> 0.0025745562 | AD7: =LN(C7/C6) -> 0.0020267538
A8: 46034 | B8: 46.34 | C8: 49.07 | D8: 1.0589124 | E8: 1.0597117 | H8: 49.107038 | K8: -0.00075452458 | N8: 0 | O8: 0 | P8: 46.34 | Q8: 49.07 | R8: 1.0589124 | S8: 1.0599915 | V8: 49.120007 | Y8: -0.0010185851 | AC8: =LN(B8/B7) -> -0.007096041 | AD8: =LN(C8/C7) -> -0.0065001245
A9: 46035 | B9: 47 | C9: 49.77 | D9: 1.0589362 | E9: 1.0597117 | H9: 49.806448 | K9: -0.00073206452 | N9: 0 | O9: 0 | P9: 47 | Q9: 49.77 | R9: 1.0589362 | S9: 1.0599915 | V9: 49.819602 | Y9: -0.00099612499 | AC9: =LN(B9/B8) -> 0.014142083 | AD9: =LN(C9/C8) -> 0.014164543 | AN9: =AVERAGE(AN22:AN200) -> 5.2201377e-05 | AY9: =AVERAGE(AY22:AY200) -> 5.7345051e-05 | BB9: =AVERAGE(BB22:BB200) -> 0.00010954643
A10: 46036 | B10: 48.06 | C10: 50.84 | D10: 1.0578444 | E10: 1.0597117 | H10: 50.929743 | K10: -0.0017636397 | N10: 0 | O10: 0 | P10: 48.06 | Q10: 50.84 | R10: 1.0578444 | S10: 1.0599915 | V10: 50.943193 | Y10: -0.0020277001 | AC10: =LN(B10/B9) -> 0.022302629 | AD10: =LN(C10/C9) -> 0.021271053 | AN10: =STDEV(AN22:AN200) -> 0.00046728368 | AY10: =STDEV(AY22:AY200) -> 0.00053771508 | BB10: =STDEV(BB22:BB200) -> 0.00070813832
A11: 46037 | B11: 47.61 | C11: 50.43 | D11: 1.0592313 | E11: 1.0597117 | F11: 1.0598224 | H11: 50.452872 | K11: -0.0004534428 | N11: 0 | O11: 0 | P11: 47.61 | Q11: 50.43 | R11: 1.0592313 | S11: 1.0599915 | T11: 1.0598224 | V11: 50.466197 | Y11: -0.00071750327 | AC11: =LN(B11/B10) -> -0.0094074071 | AD11: =LN(C11/C10) -> -0.0080972102 | AN11: =SQRT(252)*AN9/AN10 -> 1.7733792 | AY11: =SQRT(252)*AY9/AY10 -> 1.6929495 | BB11: =SQRT(252)*BB9/BB10 -> 2.4557288
A12: 46038 | B12: 47.69 | C12: 50.55 | D12: 1.0599706 | E12: 1.0597117 | F12: 1.0594668 | H12: 50.537649 | I12: 50.542932 | K12: 0.00024435748 | L12: 0.00013982189 | N12: 0 | O12: 0 | P12: 47.69 | Q12: 50.55 | R12: 1.0599706 | S12: 1.0599915 | T12: 1.0594668 | V12: 50.550996 | W12: 50.542932 | Y12: -1.9702994e-05 | Z12: 0.00013982189 | AC12: =LN(B12/B11) -> 0.0016789091 | AD12: =LN(C12/C11) -> 0.0023767094
A13: 46042 | B13: 47.6 | C13: 50.42 | D13: 1.0592437 | E13: 1.0597117 | F13: 1.0593345 | H13: 50.442275 | I13: 50.430621 | K13: -0.00044169516 | L13: -0.00021062853 | N13: 0 | O13: 0 | P13: 47.6 | Q13: 50.42 | R13: 1.0592437 | S13: 1.0599915 | T13: 1.0593345 | V13: 50.455597 | W13: 50.430621 | Y13: -0.00070575563 | Z13: -0.00021062853 | AC13: =LN(B13/B12) -> -0.0018889711 | AD13: =LN(C13/C12) -> -0.0025750237
A14: 46043 | B14: 48.75 | C14: 51.63 | D14: 1.0590769 | E14: 1.0597117 | F14: 1.0591072 | H14: 51.660944 | I14: 51.642555 | K14: -0.00059915423 | L14: -0.0002431502 | N14: 0 | O14: 0 | P14: 48.75 | Q14: 51.63 | R14: 1.0590769 | S14: 1.0599915 | T14: 1.0591072 | V14: 51.674587 | W14: 51.642555 | Y14: -0.0008632147 | Z14: -0.0002431502 | AC14: =LN(B14/B13) -> 0.023872436 | AD14: =LN(C14/C13) -> 0.023714977
A15: 46044 | B15: 48.91 | C15: 51.77 | D15: 1.0584747 | E15: 1.0597117 | F15: 1.0588833 | H15: 51.830497 | I15: 51.800933 | K15: -0.0011678993 | L15: -0.00059732528 | N15: 0 | O15: 0 | P15: 48.91 | Q15: 51.77 | R15: 1.0584747 | S15: 1.0599915 | T15: 1.0588833 | V15: 51.844186 | W15: 51.800933 | Y15: -0.0014319598 | Z15: -0.00059732528 | AC15: =LN(B15/B14) -> 0.0032766771 | AD15: =LN(C15/C14) -> 0.002707932
A16: 46045 | B16: 49.19 | C16: 52.06 | D16: 1.0583452 | E16: 1.0597117 | F16: 1.0588317 | H16: 52.127217 | I16: 52.08647 | K16: -0.0012903069 | L16: -0.00050833016 | N16: 0 | O16: 0 | P16: 49.19 | Q16: 52.06 | R16: 1.0583452 | S16: 1.0599915 | T16: 1.0588317 | V16: 52.140983 | W16: 52.08647 | Y16: -0.0015543674 | Z16: -0.00050833016 | AC16: =LN(B16/B15) -> 0.0057084763 | AD16: =LN(C16/C15) -> 0.0055860687
A17: 46048 | B17: 49.22 | C17: 52.09 | D17: 1.0583096 | E17: 1.0597117 | F17: 1.0588345 | H17: 52.159008 | I17: 52.115696 | K17: -0.0013239089 | L17: -0.00049317701 | N17: 0 | O17: 0 | P17: 49.22 | Q17: 52.09 | R17: 1.0583096 | S17: 1.0599915 | T17: 1.0588345 | V17: 52.172783 | W17: 52.115696 | Y17: -0.0015879694 | Z17: -0.00049317701 | AC17: =LN(B17/B16) -> 0.00060969416 | AD17: =LN(C17/C16) -> 0.00057609219
A18: 46049 | B18: 49.67 | C18: 52.57 | D18: 1.0583853 | E18: 1.0597117 | F18: 1.0587818 | H18: 52.635878 | I18: 52.59231 | K18: -0.00125237 | L18: -0.00042428996 | N18: 0 | O18: 0 | P18: 49.67 | Q18: 52.57 | R18: 1.0583853 | S18: 1.0599915 | T18: 1.0587818 | V18: 52.649779 | W18: 52.59231 | Y18: -0.0015164304 | Z18: -0.00042428996 | AC18: =LN(B18/B17) -> 0.0091010842 | AD18: =LN(C18/C17) -> 0.0091726231
A19: 46050 | B19: 50.05 | C19: 52.98 | D19: 1.0585415 | E19: 1.0597117 | F19: 1.0587423 | H19: 53.038569 | I19: 52.992029 | K19: -0.0011048776 | L19: -0.00022702055 | N19: 0 | O19: 0 | P19: 50.05 | Q19: 52.98 | R19: 1.0585415 | S19: 1.0599915 | T19: 1.0587423 | V19: 53.052576 | W19: 52.992029 | Y19: -0.0013689381 | Z19: -0.00022702055 | AC19: =LN(B19/B18) -> 0.0076213766 | AD19: =LN(C19/C18) -> 0.007768869
A20: 46051 | B20: 50.51 | C20: 53.46 | D20: 1.0584043 | E20: 1.0597117 | F20: 1.0587983 | H20: 53.526036 | I20: 53.477075 | K20: -0.0012344814 | L20: -0.00031934391 | N20: 0 | O20: 0 | P20: 50.51 | Q20: 53.46 | R20: 1.0584043 | S20: 1.0599915 | T20: 1.0587983 | V20: 53.540172 | W20: 53.477075 | Y20: -0.0014985419 | Z20: -0.00031934391 | AC20: =LN(B20/B19) -> 0.0091488307 | AD20: =LN(C20/C19) -> 0.0090192269
A21: 46052 | B21: 51.05 | C21: 53.97 | D21: 1.0571988 | E21: 1.0597117 | F21: 1.0585951 | G21: 1.0592088 | H21: 54.09828 | I21: 54.051654 | K21: -0.0023740637 | L21: -0.0015118097 | N21: 0 | O21: 0 | P21: 51.05 | Q21: 53.97 | R21: 1.0571988 | S21: 1.0599915 | T21: 1.0585951 | U21: 1.0592088 | V21: 54.112568 | W21: 54.051654 | Y21: -0.0026381241 | Z21: -0.0015118097 | AC21: =LN(B21/B20) -> 0.010634208 | AD21: =LN(C21/C20) -> 0.0094946259 | AK21: 0 | AV21: 0
A22: 46055 | B22: 50.05 | C22: 52.98 | D22: 1.0585415 | E22: 1.0597117 | F22: 1.0584522 | G22: 1.0589595 | H22: 53.038569 | I22: 52.982683 | J22: 53.013398 | K22: -0.0011048776 | L22: -5.0648943e-05 | M22: -0.00063019891 | N22: 0 | O22: 0 | P22: 50.05 | Q22: 52.98 | R22: 1.0585415 | S22: 1.0599915 | T22: 1.0584522 | U22: 1.0589595 | V22: 53.052576 | W22: 52.982683 | X22: 53.013398 | Y22: -0.0013689381 | Z22: -5.0648943e-05 | AA22: -0.00063019891 | AC22: =LN(B22/B21) -> -0.019783039 | AD22: =LN(C22/C21) -> -0.018513853 | AH22: =IF($AA22<AG$1,1,0) -> 0 | AI22: =IF($AA22>AG$2,1,0) -> 0 | AJ22: =AK21 -> 0 | AK22: =IF(AH21,1,IF(AI21,0,AJ21)) -> 0 | AL22: =-AK22*$AC22 -> 0 | AM22: =AK22*$AD22 -> 0 | AN22: =AL22+AM22 -> 0 | AO22: =AO21+AN22 -> 0 | AS22: =IF($AA22>AR$1,1,0) -> 0 | AT22: =IF($AA22<AR$2,1,0) -> 1 | AU22: =AV21 -> 0 | AV22: =IF(AS21,1,IF(AT21,0,AU21)) -> 0 | AW22: =AV22*$AC22 -> 0 | AX22: =-AV22*$AD22 -> 0 | AY22: =AW22+AX22 -> 0 | AZ22: =AZ21+AY22 -> 0 | BB22: =AN22+AY22 -> 0 | BC22: =BC21+BB22 -> 0
A23: 46056 | B23: 51.67 | C23: 54.62 | D23: 1.0570931 | E23: 1.0597117 | F23: 1.0582371 | G23: 1.0587858 | H23: 54.755302 | I23: 54.690223 | J23: 54.716437 | K23: -0.0024740819 | L23: -0.0012848364 | M23: -0.0017640406 | N23: 0 | O23: 0 | P23: 51.67 | Q23: 54.62 | R23: 1.0570931 | S23: 1.0599915 | T23: 1.0582371 | U23: 1.0587858 | V23: 54.769762 | W23: 54.690223 | X23: 54.716437 | Y23: -0.0027381424 | Z23: -0.0012848364 | AA23: -0.0017640406 | AC23: =LN(B23/B22) -> 0.031854837 | AD23: =LN(C23/C22) -> 0.030485632 | AH23: =IF(AA23<AG$1,1,0) -> 0 | AI23: =IF($AA23>AG$2,1,0) -> 0 | AJ23: =AK23 -> 0 | AK23: =IF(AH22,1,IF(AI22,0,AJ22)) -> 0 | AL23: =-AK23*$AC23 -> 0 | AM23: =AK23*$AD23 -> 0 | AN23: =AL23+AM23 -> 0 | AO23: =AO22+AN23 -> 0 | AS23: =IF($AA23>AR$1,1,0) -> 0 | AT23: =IF($AA23<AR$2,1,0) -> 1 | AU23: =AV22 -> 0 | AV23: =IF(AS22,1,IF(AT22,0,AU22)) -> 0 | AW23: =AV23*$AC23 -> 0 | AX23: =-AV23*$AD23 -> 0 | AY23: =AW23+AX23 -> 0 | AZ23: =AZ22+AY23 -> 0 | BB23: =AN23+AY23 -> 0 | BC23: =BC22+BB23 -> 0
A24: 46057 | B24: 52.83 | C24: 55.83 | D24: 1.0567859 | E24: 1.0597117 | F24: 1.058008 | G24: 1.0585576 | H24: 55.984567 | I24: 55.906666 | J24: 55.935653 | K24: -0.0027647075 | L24: -0.0013722573 | M24: -0.0018906147 | N24: 0 | O24: 0 | P24: 52.83 | Q24: 55.83 | R24: 1.0567859 | S24: 1.0599915 | T24: 1.058008 | U24: 1.0585576 | V24: 55.999352 | W24: 55.906666 | X24: 55.935653 | Y24: -0.003028768 | Z24: -0.0013722573 | AA24: -0.0018906147 | AC24: =LN(B24/B23) -> 0.022201869 | AD24: =LN(C24/C23) -> 0.021911243 | AH24: =IF(AA24<AG$1,1,0) -> 0 | AI24: =IF($AA24>AG$2,1,0) -> 0 | AJ24: =AK24 -> 0 | AK24: =IF(AH23,1,IF(AI23,0,AJ23)) -> 0 | AL24: =-AK24*$AC24 -> 0 | AM24: =AK24*$AD24 -> 0 | AN24: =AL24+AM24 -> 0 | AO24: =AO23+AN24 -> 0 | AS24: =IF($AA24>AR$1,1,0) -> 0 | AT24: =IF($AA24<AR$2,1,0) -> 1 | AU24: =AV23 -> 0 | AV24: =IF(AS23,1,IF(AT23,0,AU23)) -> 0 | AW24: =AV24*$AC24 -> 0 | AX24: =-AV24*$AD24 -> 0 | AY24: =AW24+AX24 -> 0 | AZ24: =AZ23+AY24 -> 0 | BB24: =AN24+AY24 -> 0 | BC24: =BC23+BB24 -> 0
A25: 46058 | B25: 52.21 | C25: 55.19 | D25: 1.0570772 | E25: 1.0597117 | F25: 1.0578682 | G25: 1.0583758 | H25: 55.327546 | I25: 55.238597 | J25: 55.267292 | K25: -0.0024891257 | L25: -0.00088015925 | M25: -0.0013994902 | N25: 0 | O25: 0 | P25: 52.21 | Q25: 55.19 | R25: 1.0570772 | S25: 1.0599915 | T25: 1.0578682 | U25: 1.0583758 | V25: 55.342158 | W25: 55.238597 | X25: 55.267292 | Y25: -0.0027531861 | Z25: -0.00088015925 | AA25: -0.0013994902 | AC25: =LN(B25/B24) -> -0.011805164 | AD25: =LN(C25/C24) -> -0.011529582 | AH25: =IF(AA25<AG$1,1,0) -> 0 | AI25: =IF($AA25>AG$2,1,0) -> 0 | AJ25: =AK25 -> 0 | AK25: =IF(AH24,1,IF(AI24,0,AJ24)) -> 0 | AL25: =-AK25*$AC25 -> 0 | AM25: =AK25*$AD25 -> 0 | AN25: =AL25+AM25 -> 0 | AO25: =AO24+AN25 -> 0 | AS25: =IF($AA25>AR$1,1,0) -> 0 | AT25: =IF($AA25<AR$2,1,0) -> 1 | AU25: =AV24 -> 0 | AV25: =IF(AS24,1,IF(AT24,0,AU24)) -> 0 | AW25: =AV25*$AC25 -> 0 | AX25: =-AV25*$AD25 -> 0 | AY25: =AW25+AX25 -> 0 | AZ25: =AZ24+AY25 -> 0 | BB25: =AN25+AY25 -> 0 | BC25: =BC24+BB25 -> 0
A26: 46059 | B26: 53.25 | C26: 56.24 | D26: 1.0561502 | E26: 1.0597117 | F26: 1.0576487 | G26: 1.0582402 | H26: 56.429646 | I26: 56.331484 | J26: 56.35851 | K26: -0.0033664128 | L26: -0.001625344 | M26: -0.002105005 | N26: 0 | O26: 0 | P26: 53.25 | Q26: 56.24 | R26: 1.0561502 | S26: 1.0599915 | T26: 1.0576487 | U26: 1.0582402 | V26: 56.444549 | W26: 56.331484 | X26: 56.35851 | Y26: -0.0036304732 | Z26: -0.001625344 | AA26: -0.002105005 | AC26: =LN(B26/B25) -> 0.019723757 | AD26: =LN(C26/C25) -> 0.01884647 | AH26: =IF(AA26<AG$1,1,0) -> 1 | AI26: =IF($AA26>AG$2,1,0) -> 0 | AJ26: =AK26 -> 0 | AK26: =IF(AH25,1,IF(AI25,0,AJ25)) -> 0 | AL26: =-AK26*$AC26 -> 0 | AM26: =AK26*$AD26 -> 0 | AN26: =AL26+AM26 -> 0 | AO26: =AO25+AN26 -> 0 | AS26: =IF($AA26>AR$1,1,0) -> 0 | AT26: =IF($AA26<AR$2,1,0) -> 1 | AU26: =AV25 -> 0 | AV26: =IF(AS25,1,IF(AT25,0,AU25)) -> 0 | AW26: =AV26*$AC26 -> 0 | AX26: =-AV26*$AD26 -> 0 | AY26: =AW26+AX26 -> 0 | AZ26: =AZ25+AY26 -> 0 | BB26: =AN26+AY26 -> 0 | BC26: =BC25+BB26 -> 0
A27: 46062 | B27: 53.64 | C27: 56.69 | D27: 1.0568606 | E27: 1.0597117 | F27: 1.0575038 | G27: 1.0581692 | H27: 56.842934 | I27: 56.732279 | J27: 56.764005 | K27: -0.0026940858 | L27: -0.00074550674 | M27: -0.0013045865 | N27: 0 | O27: 0 | P27: 53.64 | Q27: 56.69 | R27: 1.0568606 | S27: 1.0599915 | T27: 1.0575038 | U27: 1.0581692 | V27: 56.857946 | W27: 56.732279 | X27: 56.764005 | Y27: -0.0029581462 | Z27: -0.00074550674 | AA27: -0.0013045865 | AC27: =LN(B27/B26) -> 0.0072972538 | AD27: =LN(C27/C26) -> 0.0079695808 | AH27: =IF(AA27<AG$1,1,0) -> 0 | AI27: =IF($AA27>AG$2,1,0) -> 0 | AJ27: =AK27 -> 1 | AK27: =IF(AH26,1,IF(AI26,0,AJ26)) -> 1 | AL27: =-AK27*$AC27 -> -0.0072972538 | AM27: =AK27*$AD27 -> 0.0079695808 | AN27: =AL27+AM27 -> 0.00067232701 | AO27: =AO26+AN27 -> 0.00067232701 | AS27: =IF($AA27>AR$1,1,0) -> 0 | AT27: =IF($AA27<AR$2,1,0) -> 1 | AU27: =AV26 -> 0 | AV27: =IF(AS26,1,IF(AT26,0,AU26)) -> 0 | AW27: =AV27*$AC27 -> 0 | AX27: =-AV27*$AD27 -> 0 | AY27: =AW27+AX27 -> 0 | AZ27: =AZ26+AY27 -> 0 | BB27: =AN27+AY27 -> 0.00067232701 | BC27: =BC26+BB27 -> 0.00067232701
A28: 46063 | B28: 53.58 | C28: 56.64 | D28: 1.0571109 | E28: 1.0597117 | F28: 1.0573764 | G28: 1.0580791 | H28: 56.779351 | I28: 56.661055 | J28: 56.696704 | K28: -0.0024572704 | L28: -0.00037167258 | M28: -0.0010006292 | N28: 0 | O28: 0 | P28: 53.58 | Q28: 56.64 | R28: 1.0571109 | S28: 1.0599915 | T28: 1.0573764 | U28: 1.0580791 | V28: 56.794346 | W28: 56.661055 | X28: 56.696704 | Y28: -0.0027213309 | Z28: -0.00037167258 | AA28: -0.0010006292 | AC28: =LN(B28/B27) -> -0.0011191943 | AD28: =LN(C28/C27) -> -0.00088237895 | AH28: =IF(AA28<AG$1,1,0) -> 0 | AI28: =IF($AA28>AG$2,1,0) -> 0 | AJ28: =AK28 -> 1 | AK28: =IF(AH27,1,IF(AI27,0,AJ27)) -> 1 | AL28: =-AK28*$AC28 -> 0.0011191943 | AM28: =AK28*$AD28 -> -0.00088237895 | AN28: =AL28+AM28 -> 0.00023681535 | AO28: =AO27+AN28 -> 0.00090914236 | AS28: =IF($AA28>AR$1,1,0) -> 0 | AT28: =IF($AA28<AR$2,1,0) -> 1 | AU28: =AV27 -> 0 | AV28: =IF(AS27,1,IF(AT27,0,AU27)) -> 0 | AW28: =AV28*$AC28 -> 0 | AX28: =-AV28*$AD28 -> 0 | AY28: =AW28+AX28 -> 0 | AZ28: =AZ27+AY28 -> 0 | BB28: =AN28+AY28 -> 0.00023681535 | BC28: =BC27+BB28 -> 0.00090914236
A29: 46064 | B29: 54.98 | C29: 58.07 | D29: 1.0562023 | E29: 1.0597117 | F29: 1.0571425 | G29: 1.0579424 | H29: 58.262947 | I29: 58.134554 | J29: 58.173188 | K29: -0.003317159 | L29: -0.0011110361 | M29: -0.0017753896 | N29: 0 | O29: 0 | P29: 54.98 | Q29: 58.07 | R29: 1.0562023 | S29: 1.0599915 | T29: 1.0571425 | U29: 1.0579424 | V29: 58.278334 | W29: 58.134554 | X29: 58.173188 | Y29: -0.0035812195 | Z29: -0.0011110361 | AA29: -0.0017753896 | AC29: =LN(B29/B28) -> 0.025793619 | AD29: =LN(C29/C28) -> 0.02493373 | AH29: =IF(AA29<AG$1,1,0) -> 0 | AI29: =IF($AA29>AG$2,1,0) -> 0 | AJ29: =AK29 -> 1 | AK29: =IF(AH28,1,IF(AI28,0,AJ28)) -> 1 | AL29: =-AK29*$AC29 -> -0.025793619 | AM29: =AK29*$AD29 -> 0.02493373 | AN29: =AL29+AM29 -> -0.00085988862 | AO29: =AO28+AN29 -> 4.9253734e-05 | AS29: =IF($AA29>AR$1,1,0) -> 0 | AT29: =IF($AA29<AR$2,1,0) -> 1 | AU29: =AV28 -> 0 | AV29: =IF(AS28,1,IF(AT28,0,AU28)) -> 0 | AW29: =AV29*$AC29 -> 0 | AX29: =-AV29*$AD29 -> 0 | AY29: =AW29+AX29 -> 0 | AZ29: =AZ28+AY29 -> 0 | BB29: =AN29+AY29 -> -0.00085988862 | BC29: =BC28+BB29 -> 4.9253734e-05
A30: 46065 | B30: 53.98 | C30: 56.98 | D30: 1.0555761 | E30: 1.0597117 | F30: 1.0568597 | G30: 1.057829 | H30: 57.203236 | I30: 57.06455 | J30: 57.107731 | K30: -0.0039101342 | L30: -0.0014827597 | M30: -0.002239164 | N30: 0 | O30: 0 | P30: 53.98 | Q30: 56.98 | R30: 1.0555761 | S30: 1.0599915 | T30: 1.0568597 | U30: 1.057829 | V30: 57.218343 | W30: 57.06455 | X30: 57.107731 | Y30: -0.0041741947 | Z30: -0.0014827597 | AA30: -0.002239164 | AC30: =LN(B30/B29) -> -0.018355875 | AD30: =LN(C30/C29) -> -0.01894885 | AH30: =IF(AA30<AG$1,1,0) -> 1 | AI30: =IF($AA30>AG$2,1,0) -> 0 | AJ30: =AK30 -> 1 | AK30: =IF(AH29,1,IF(AI29,0,AJ29)) -> 1 | AL30: =-AK30*$AC30 -> 0.018355875 | AM30: =AK30*$AD30 -> -0.01894885 | AN30: =AL30+AM30 -> -0.00059297517 | AO30: =AO29+AN30 -> -0.00054372143 | AS30: =IF($AA30>AR$1,1,0) -> 0 | AT30: =IF($AA30<AR$2,1,0) -> 1 | AU30: =AV29 -> 0 | AV30: =IF(AS29,1,IF(AT29,0,AU29)) -> 0 | AW30: =AV30*$AC30 -> 0 | AX30: =-AV30*$AD30 -> 0 | AY30: =AW30+AX30 -> 0 | AZ30: =AZ29+AY30 -> 0 | BB30: =AN30+AY30 -> -0.00059297517 | BC30: =BC29+BB30 -> -0.00054372143
A31: 46066 | B31: 54.35 | C31: 57.41 | D31: 1.0563017 | E31: 1.0597117 | F31: 1.0567699 | G31: 1.0576825 | H31: 57.595329 | I31: 57.440322 | J31: 57.493005 | K31: -0.0032229651 | L31: -0.00052802817 | M31: -0.0014447895 | N31: 0 | O31: 0 | P31: 54.35 | Q31: 57.41 | R31: 1.0563017 | S31: 1.0599915 | T31: 1.0567699 | U31: 1.0576825 | V31: 57.61054 | W31: 57.440322 | X31: 57.493005 | Y31: -0.0034870255 | Z31: -0.00052802817 | AA31: -0.0014447895 | AC31: =LN(B31/B30) -> 0.006831006 | AD31: =LN(C31/C30) -> 0.0075181751 | AH31: =IF(AA31<AG$1,1,0) -> 0 | AI31: =IF($AA31>AG$2,1,0) -> 0 | AJ31: =AK31 -> 1 | AK31: =IF(AH30,1,IF(AI30,0,AJ30)) -> 1 | AL31: =-AK31*$AC31 -> -0.006831006 | AM31: =AK31*$AD31 -> 0.0075181751 | AN31: =AL31+AM31 -> 0.00068716913 | AO31: =AO30+AN31 -> 0.0001434477 | AS31: =IF($AA31>AR$1,1,0) -> 0 | AT31: =IF($AA31<AR$2,1,0) -> 1 | AU31: =AV30 -> 0 | AV31: =IF(AS30,1,IF(AT30,0,AU30)) -> 0 | AW31: =AV31*$AC31 -> 0 | AX31: =-AV31*$AD31 -> 0 | AY31: =AW31+AX31 -> 0 | AZ31: =AZ30+AY31 -> 0 | BB31: =AN31+AY31 -> 0.00068716913 | BC31: =BC30+BB31 -> 0.0001434477
A32: 46070 | B32: 53.75 | C32: 56.79 | D32: 1.0565581 | E32: 1.0597117 | F32: 1.0565716 | G32: 1.0575119 | H32: 56.959502 | I32: 56.801385 | J32: 56.850435 | K32: -0.0029802688 | L32: -0.00020044694 | M32: -0.0010636158 | N32: 0 | O32: 0 | P32: 53.75 | Q32: 56.79 | R32: 1.0565581 | S32: 1.0599915 | T32: 1.0565716 | U32: 1.0575119 | V32: 56.974545 | W32: 56.801385 | X32: 56.850435 | Y32: -0.0032443293 | Z32: -0.00020044694 | AA32: -0.0010636158 | AC32: =LN(B32/B31) -> -0.011100947 | AD32: =LN(C32/C31) -> -0.01085825 | AH32: =IF(AA32<AG$1,1,0) -> 0 | AI32: =IF($AA32>AG$2,1,0) -> 0 | AJ32: =AK32 -> 1 | AK32: =IF(AH31,1,IF(AI31,0,AJ31)) -> 1 | AL32: =-AK32*$AC32 -> 0.011100947 | AM32: =AK32*$AD32 -> -0.01085825 | AN32: =AL32+AM32 -> 0.00024269627 | AO32: =AO31+AN32 -> 0.00038614397 | AS32: =IF($AA32>AR$1,1,0) -> 0 | AT32: =IF($AA32<AR$2,1,0) -> 1 | AU32: =AV31 -> 0 | AV32: =IF(AS31,1,IF(AT31,0,AU31)) -> 0 | AW32: =AV32*$AC32 -> 0 | AX32: =-AV32*$AD32 -> 0 | AY32: =AW32+AX32 -> 0 | AZ32: =AZ31+AY32 -> 0 | BB32: =AN32+AY32 -> 0.00024269627 | BC32: =BC31+BB32 -> 0.00038614397
A33: 46071 | B33: 54.78 | C33: 57.9 | D33: 1.0569551 | E33: 1.0597117 | F33: 1.0565578 | G33: 1.0573975 | H33: 58.051005 | I33: 57.878993 | J33: 57.930501 | K33: -0.0026046349 | L33: 0.00036288199 | M33: -0.000526649 | N33: 0 | O33: 0 | P33: 54.78 | Q33: 57.9 | R33: 1.0569551 | S33: 1.0599915 | T33: 1.0565578 | U33: 1.0573975 | V33: 58.066336 | W33: 57.878993 | X33: 57.930501 | Y33: -0.0028686954 | Z33: 0.00036288199 | AA33: -0.000526649 | AC33: =LN(B33/B32) -> 0.018981497 | AD33: =LN(C33/C32) -> 0.019357131 | AH33: =IF(AA33<AG$1,1,0) -> 0 | AI33: =IF($AA33>AG$2,1,0) -> 0 | AJ33: =AK33 -> 1 | AK33: =IF(AH32,1,IF(AI32,0,AJ32)) -> 1 | AL33: =-AK33*$AC33 -> -0.018981497 | AM33: =AK33*$AD33 -> 0.019357131 | AN33: =AL33+AM33 -> 0.00037563386 | AO33: =AO32+AN33 -> 0.00076177783 | AS33: =IF($AA33>AR$1,1,0) -> 0 | AT33: =IF($AA33<AR$2,1,0) -> 1 | AU33: =AV32 -> 0 | AV33: =IF(AS32,1,IF(AT32,0,AU32)) -> 0 | AW33: =AV33*$AC33 -> 0 | AX33: =-AV33*$AD33 -> 0 | AY33: =AW33+AX33 -> 0 | AZ33: =AZ32+AY33 -> 0 | BB33: =AN33+AY33 -> 0.00037563386 | BC33: =BC32+BB33 -> 0.00076177783
A34: 46072 | B34: 55.18 | C34: 58.29 | D34: 1.056361 | E34: 1.0597117 | F34: 1.0565153 | G34: 1.0572617 | H34: 58.47489 | I34: 58.30086 | J34: 58.347192 | K34: -0.0031668724 | L34: -0.00018629451 | M34: -0.00098067359 | N34: 0 | O34: 0 | P34: 55.18 | Q34: 58.29 | R34: 1.056361 | S34: 1.0599915 | T34: 1.0565153 | U34: 1.0572617 | V34: 58.490333 | W34: 58.30086 | X34: 58.347192 | Y34: -0.0034309329 | Z34: -0.00018629451 | AA34: -0.00098067359 | AC34: =LN(B34/B33) -> 0.007275405 | AD34: =LN(C34/C33) -> 0.0067131675 | AH34: =IF(AA34<AG$1,1,0) -> 0 | AI34: =IF($AA34>AG$2,1,0) -> 0 | AJ34: =AK34 -> 1 | AK34: =IF(AH33,1,IF(AI33,0,AJ33)) -> 1 | AL34: =-AK34*$AC34 -> -0.007275405 | AM34: =AK34*$AD34 -> 0.0067131675 | AN34: =AL34+AM34 -> -0.00056223748 | AO34: =AO33+AN34 -> 0.00019954036 | AS34: =IF($AA34>AR$1,1,0) -> 0 | AT34: =IF($AA34<AR$2,1,0) -> 1 | AU34: =AV33 -> 0 | AV34: =IF(AS33,1,IF(AT33,0,AU33)) -> 0 | AW34: =AV34*$AC34 -> 0 | AX34: =-AV34*$AD34 -> 0 | AY34: =AW34+AX34 -> 0 | AZ34: =AZ33+AY34 -> 0 | BB34: =AN34+AY34 -> -0.00056223748 | BC34: =BC33+BB34 -> 0.00019954036
... A156: 46248 | B156: 61.91 | C156: 65.66 | D156: 1.0605718 | E156: 1.0597117 | F156: 1.0626294 | G156: 1.0624332 | H156: 65.606749 | I156: 65.785615 | J156: 65.77933 | K156: 0.00081133886 | L156: -0.0019112904 | M156: -0.0018157443 | N156: 0 | O156: 0 | P156: 61.91 | Q156: 65.66 | R156: 1.0605718 | S156: 1.0599915 | T156: 1.0626294 | U156: 1.0624332 | V156: 65.624076 | W156: 65.785615 | X156: 65.77933 | Y156: 0.00054727839 | Z156: -0.0019112904 | AA156: -0.0018157443 | AC156: =LN(B156/B155) -> 0.01382473 | AD156: =LN(C156/C155) -> 0.013647379 | AH156: =IF(AA156<AG$1,1,0) -> 0 | AI156: =IF($AA156>AG$2,1,0) -> 0 | AJ156: =AK156 -> 0 | AK156: =IF(AH155,1,IF(AI155,0,AJ155)) -> 0 | AL156: =-AK156*$AC156 -> 0 | AM156: =AK156*$AD156 -> 0 | AN156: =AL156+AM156 -> 0 | AO156: =AO155+AN156 -> 0.0070471859 | AS156: =IF($AA156>AR$1,1,0) -> 0 | AT156: =IF($AA156<AR$2,1,0) -> 1 | AU156: =AV155 -> 0 | AV156: =IF(AS155,1,IF(AT155,0,AU155)) -> 0 | AW156: =AV156*$AC156 -> 0 | AX156: =-AV156*$AD156 -> 0 | AY156: =AW156+AX156 -> 0 | AZ156: =AZ155+AY156 -> 0.0077415819 | BB156: =AN156+AY156 -> 0 | BC156: =BC155+BB156 -> 0.014788768

Sheet XLF_IYF
A1: date | B1: XLF | C1: IYF | D1: IYF/XLF | E1: IYF/XLF avg | F1: IYF/XLF 10 dma | G1: IYF/XLF 20 dma | H1: XLF avg | I1: XLF 10 dma | J1: XLF 20 dma | K1: avg diff | L1: 10 dma diff | M1: 20 dma diff | N1: XLF div | O1: IYF div | P1: XLF* | Q1: IYF* | R1: IYF*/XLF* | S1: IYF*/XLF* avg | T1: IYF*/XLF* 10 dma | U1: IYF*/XLF* 20 dma | V1: XLF* avg | W1: XLF* 10 dma | X1: XLF* 20 dma | Y1: avg diff* | Z1: 10 dma diff* | AA1: 20 dma diff* | AC1: =_xlfn.CONCAT(B1," rtn") -> XLF rtn | AD1: =_xlfn.CONCAT(C1," rtn") -> IYF rtn | AF1: signal | AG1: -0.004 | AH1: under | AI1: over | AJ1: yday | AK1: position | AO1: =AO156 -> 0.019435292 | AQ1: signal | AR1: 0.004 | AS1: over | AT1: under | AU1: yday | AV1: position | AZ1: =AZ156 -> 0.029060433 | BC1: =BC156 -> 0.048495725
A2: 46024 | B2: 54.93 | C2: 129.65 | D2: 2.3602767 | E2: 2.3831652 | N2: 0 | O2: 0 | P2: 54.93 | Q2: 129.65 | R2: 2.3602767 | S2: 2.3836499 | AG2: -0.002 | AR2: 0
A3: 46027 | B3: 56.13 | C3: 132.78 | D3: 2.3655799 | E3: 2.3831652 | H3: 133.76706 | K3: -0.0074063246 | N3: 0 | O3: 0 | P3: 56.13 | Q3: 132.78 | R3: 2.3655799 | S3: 2.3836499 | V3: 133.79427 | Y3: -0.0076097054 | AC3: =LN(B3/B2) -> 0.021610782 | AD3: =LN(C3/C2) -> 0.023855111
A4: 46028 | B4: 56.4 | C4: 133 | D4: 2.358156 | E4: 2.3831652 | H4: 134.41052 | K4: -0.010549549 | N4: 0 | O4: 0 | P4: 56.4 | Q4: 133 | R4: 2.358156 | S4: 2.3836499 | V4: 134.43786 | Y4: -0.01075293 | AC4: =LN(B4/B3) -> 0.0047987295 | AD4: =LN(C4/C3) -> 0.0016555049
A5: 46029 | B5: 55.61 | C5: 130.84 | D5: 2.3528142 | E5: 2.3831652 | H5: 132.52782 | K5: -0.012817357 | N5: 0 | O5: 0 | P5: 55.61 | Q5: 130.84 | R5: 2.3528142 | S5: 2.3836499 | V5: 132.55477 | Y5: -0.013020738 | AC5: =LN(B5/B4) -> -0.014106117 | AD5: =LN(C5/C4) -> -0.016373926
A6: 46030 | B6: 55.9 | C6: 131.79 | D6: 2.3576029 | E6: 2.3831652 | H6: 133.21893 | K6: -0.010784152 | N6: 0 | O6: 0 | P6: 55.9 | Q6: 131.79 | R6: 2.3576029 | S6: 2.3836499 | V6: 133.24603 | Y6: -0.010987533 | AC6: =LN(B6/B5) -> 0.005201339 | AD6: =LN(C6/C5) -> 0.007234544
A7: 46031 | B7: 55.73 | C7: 131.56 | D7: 2.3606675 | E7: 2.3831652 | H7: 132.8138 | K7: -0.0094850992 | N7: 0 | O7: 0 | P7: 55.73 | Q7: 131.56 | R7: 2.3606675 | S7: 2.3836499 | V7: 132.84081 | Y7: -0.00968848 | AC7: =LN(B7/B6) -> -0.0030457786 | AD7: =LN(C7/C6) -> -0.0017467253
A8: 46034 | B8: 55.29 | C8: 131.07 | D8: 2.3705914 | E8: 2.3831652 | H8: 131.7652 | K8: -0.0052900476 | N8: 0 | O8: 0 | P8: 55.29 | Q8: 131.07 | R8: 2.3705914 | S8: 2.3836499 | V8: 131.792 | Y8: -0.0054934284 | AC8: =LN(B8/B7) -> -0.0079265412 | AD8: =LN(C8/C7) -> -0.0037314897
A9: 46035 | B9: 54.23 | C9: 129.16 | D9: 2.3817075 | E9: 2.3831652 | H9: 129.23905 | K9: -0.00061183385 | N9: 0 | O9: 0 | P9: 54.23 | Q9: 129.16 | R9: 2.3817075 | S9: 2.3836499 | V9: 129.26534 | Y9: -0.00081521469 | AC9: =LN(B9/B8) -> -0.019357799 | AD9: =LN(C9/C8) -> -0.014679586 | AN9: =AVERAGE(AN22:AN200) -> 0.00014396513 | AY9: =AVERAGE(AY22:AY200) -> 0.00021526247 | BB9: =AVERAGE(BB22:BB200) -> 0.00035922759
A10: 46036 | B10: 54.15 | C10: 128.99 | D10: 2.3820868 | E10: 2.3831652 | H10: 129.0484 | K10: -0.00045261036 | N10: 0 | O10: 0 | P10: 54.15 | Q10: 128.99 | R10: 2.3820868 | S10: 2.3836499 | V10: 129.07464 | Y10: -0.0006559912 | AC10: =LN(B10/B9) -> -0.0014762874 | AD10: =LN(C10/C9) -> -0.0013170639 | AN10: =STDEV(AN22:AN200) -> 0.0010192111 | AY10: =STDEV(AY22:AY200) -> 0.0012221791 | BB10: =STDEV(BB22:BB200) -> 0.0015716456
A11: 46037 | B11: 54.37 | C11: 129.76 | D11: 2.3866103 | E11: 2.3831652 | F11: 2.3676093 | H11: 129.57269 | K11: 0.0014445403 | N11: 0 | O11: 0 | P11: 54.37 | Q11: 129.76 | R11: 2.3866103 | S11: 2.3836499 | T11: 2.3676093 | V11: 129.59905 | Y11: 0.0012411595 | AC11: =LN(B11/B10) -> 0.0040545577 | AD11: =LN(C11/C10) -> 0.0059517084 | AN11: =SQRT(252)*AN9/AN10 -> 2.2422985 | AY11: =SQRT(252)*AY9/AY10 -> 2.7959778 | BB11: =SQRT(252)*BB9/BB10 -> 3.6284014
A12: 46038 | B12: 54.44 | C12: 129.84 | D12: 2.385011 | E12: 2.3831652 | F12: 2.3700828 | H12: 129.73951 | I12: 128.89265 | K12: 0.00077422653 | L12: 0.0073230216 | N12: 0 | O12: 0 | P12: 54.44 | Q12: 129.84 | R12: 2.385011 | S12: 2.3836499 | T12: 2.3700828 | V12: 129.7659 | W12: 128.89265 | Y12: 0.00057084569 | Z12: 0.0073230216 | AC12: =LN(B12/B11) -> 0.0012866466 | AD12: =LN(C12/C11) -> 0.00061633284
A13: 46042 | B13: 53.2 | C13: 126.95 | D13: 2.3862782 | E13: 2.3831652 | F13: 2.3721526 | H13: 126.78439 | I13: 126.0884 | K13: 0.0013053929 | L13: 0.0068100379 | N13: 0 | O13: 0 | P13: 53.2 | Q13: 126.95 | R13: 2.3862782 | S13: 2.3836499 | T13: 2.3721526 | V13: 126.81018 | W13: 126.0884 | Y13: 0.0011020121 | Z13: 0.0068100379 | AC13: =LN(B13/B12) -> -0.023040781 | AD13: =LN(C13/C12) -> -0.022509615
A14: 46043 | B14: 53.46 | C14: 127.82 | D14: 2.3909465 | E14: 2.3831652 | F14: 2.3754316 | H14: 127.40401 | I14: 126.81528 | K14: 0.0032597946 | L14: 0.0078915055 | N14: 0 | O14: 0 | P14: 53.46 | Q14: 127.82 | R14: 2.3909465 | S14: 2.3836499 | T14: 2.3754316 | V14: 127.42993 | W14: 126.81528 | Y14: 0.0030564138 | Z14: 0.0078915055 | AC14: =LN(B14/B13) -> 0.0048753144 | AD14: =LN(C14/C13) -> 0.0068297161
A15: 46044 | B15: 53.81 | C15: 128.41 | D15: 2.3863594 | E15: 2.3831652 | F15: 2.3787862 | H15: 128.23812 | I15: 127.82198 | K15: 0.0013394275 | L15: 0.0045897841 | N15: 0 | O15: 0 | P15: 53.81 | Q15: 128.41 | R15: 2.3863594 | S15: 2.3836499 | T15: 2.3787862 | V15: 128.2642 | W15: 127.82198 | Y15: 0.0011360466 | Z15: 0.0045897841 | AC15: =LN(B15/B14) -> 0.0065256128 | AD15: =LN(C15/C14) -> 0.0046052456
A16: 46045 | B16: 53.07 | C16: 126.73 | D16: 2.3879781 | E16: 2.3831652 | F16: 2.3818237 | H16: 126.47458 | I16: 126.24218 | K16: 0.0020175234 | L16: 0.0038567046 | N16: 0 | O16: 0 | P16: 53.07 | Q16: 126.73 | R16: 2.3879781 | S16: 2.3836499 | T16: 2.3818237 | V16: 126.5003 | W16: 126.24218 | Y16: 0.0018141425 | Z16: 0.0038567046 | AC16: =LN(B16/B15) -> -0.013847527 | AD16: =LN(C16/C15) -> -0.013169431
A17: 46048 | B17: 53.41 | C17: 127.49 | D17: 2.3870062 | E17: 2.3831652 | F17: 2.3844575 | H17: 127.28485 | I17: 127.2132 | K17: 0.0016104169 | L17: 0.0021734892 | N17: 0 | O17: 0 | P17: 53.41 | Q17: 127.49 | R17: 2.3870062 | S17: 2.3836499 | T17: 2.3844575 | V17: 127.31074 | W17: 127.2132 | Y17: 0.0014070361 | Z17: 0.0021734892 | AC17: =LN(B17/B16) -> 0.0063861975 | AD17: =LN(C17/C16) -> 0.0059790911
A18: 46049 | B18: 53 | C18: 126.82 | D18: 2.3928302 | E18: 2.3831652 | F18: 2.3866814 | H18: 126.30776 | I18: 126.37625 | K18: 0.0040473258 | L18: 0.0035051894 | N18: 0 | O18: 0 | P18: 53 | Q18: 126.82 | R18: 2.3928302 | S18: 2.3836499 | T18: 2.3866814 | V18: 126.33345 | W18: 126.37625 | Y18: 0.003843945 | Z18: 0.0035051894 | AC18: =LN(B18/B17) -> -0.0077060808 | AD18: =LN(C18/C17) -> -0.0052691719
A19: 46050 | B19: 52.99 | C19: 126.73 | D19: 2.3915833 | E19: 2.3831652 | F19: 2.387669 | H19: 126.28392 | I19: 126.47025 | K19: 0.0035261037 | L19: 0.002051747 | N19: 0 | O19: 0 | P19: 52.99 | Q19: 126.73 | R19: 2.3915833 | S19: 2.3836499 | T19: 2.387669 | V19: 126.30961 | W19: 126.47025 | Y19: 0.0033227229 | Z19: 0.002051747 | AC19: =LN(B19/B18) -> -0.00018869705 | AD19: =LN(C19/C18) -> -0.00070991918
A20: 46051 | B20: 53.55 | C20: 127.72 | D20: 2.3850607 | E20: 2.3831652 | F20: 2.3879664 | H20: 127.6185 | I20: 127.85968 | K20: 0.00079505206 | L20: -0.001093006 | N20: 0 | O20: 0 | P20: 53.55 | Q20: 127.72 | R20: 2.3850607 | S20: 2.3836499 | T20: 2.3879664 | V20: 127.64445 | W20: 127.85968 | Y20: 0.00059167122 | Z20: -0.001093006 | AC20: =LN(B20/B19) -> 0.01051258 | AD20: =LN(C20/C19) -> 0.0077815288
A21: 46052 | B21: 53.44 | C21: 127.7 | D21: 2.3895958 | E21: 2.3831652 | F21: 2.3882649 | G21: 2.3779371 | H21: 127.35635 | I21: 127.61292 | K21: 0.0026947149 | L21: 0.00068211239 | N21: 0 | O21: 0 | P21: 53.44 | Q21: 127.7 | R21: 2.3895958 | S21: 2.3836499 | T21: 2.3882649 | U21: 2.3779371 | V21: 127.38225 | W21: 127.61292 | Y21: 0.0024913341 | Z21: 0.00068211239 | AC21: =LN(B21/B20) -> -0.0020562677 | AD21: =LN(C21/C20) -> -0.00015660481 | AK21: 0 | AV21: 0
A22: 46055 | B22: 54.03 | C22: 128.57 | D22: 2.3796039 | E22: 2.3831652 | F22: 2.3877242 | G22: 2.3789035 | H22: 128.76242 | I22: 129.03796 | J22: 128.47994 | K22: -0.0014954637 | L22: -0.003633083 | M22: 0.00070069252 | N22: 0 | O22: 0 | P22: 54.03 | Q22: 128.57 | R22: 2.3796039 | S22: 2.3836499 | T22: 2.3877242 | U22: 2.3789035 | V22: 128.78861 | W22: 129.03796 | X22: 128.47994 | Y22: -0.0016988445 | Z22: -0.003633083 | AA22: 0.00070069252 | AC22: =LN(B22/B21) -> 0.010979919 | AD22: =LN(C22/C21) -> 0.0067897401 | AH22: =IF($AA22<AG$1,1,0) -> 0 | AI22: =IF($AA22>AG$2,1,0) -> 1 | AJ22: =AK21 -> 0 | AK22: =IF(AH21,1,IF(AI21,0,AJ21)) -> 0 | AL22: =-AK22*$AC22 -> 0 | AM22: =AK22*$AD22 -> 0 | AN22: =AL22+AM22 -> 0 | AO22: =AO21+AN22 -> 0 | AS22: =IF($AA22>AR$1,1,0) -> 0 | AT22: =IF($AA22<AR$2,1,0) -> 0 | AU22: =AV21 -> 0 | AV22: =IF(AS21,1,IF(AT21,0,AU21)) -> 0 | AW22: =AV22*$AC22 -> 0 | AX22: =-AV22*$AD22 -> 0 | AY22: =AW22+AX22 -> 0 | AZ22: =AZ21+AY22 -> 0 | BB22: =AN22+AY22 -> 0 | BC22: =BC21+BB22 -> 0
A23: 46056 | B23: 53.53 | C23: 127.68 | D23: 2.3852046 | E23: 2.3831652 | F23: 2.3876169 | G23: 2.3798847 | H23: 127.57083 | I23: 127.81488 | J23: 127.3427 | K23: 0.00085537041 | L23: -0.0010558205 | M23: 0.0026452231 | N23: 0 | O23: 0 | P23: 53.53 | Q23: 127.68 | R23: 2.3852046 | S23: 2.3836499 | T23: 2.3876169 | U23: 2.3798847 | V23: 127.59678 | W23: 127.81488 | X23: 127.3427 | Y23: 0.00065198957 | Z23: -0.0010558205 | AA23: 0.0026452231 | AC23: =LN(B23/B22) -> -0.0092972035 | AD23: =LN(C23/C22) -> -0.0069463694 | AH23: =IF(AA23<AG$1,1,0) -> 0 | AI23: =IF($AA23>AG$2,1,0) -> 1 | AJ23: =AK23 -> 0 | AK23: =IF(AH22,1,IF(AI22,0,AJ22)) -> 0 | AL23: =-AK23*$AC23 -> 0 | AM23: =AK23*$AD23 -> 0 | AN23: =AL23+AM23 -> 0 | AO23: =AO22+AN23 -> 0 | AS23: =IF($AA23>AR$1,1,0) -> 0 | AT23: =IF($AA23<AR$2,1,0) -> 0 | AU23: =AV22 -> 0 | AV23: =IF(AS22,1,IF(AT22,0,AU22)) -> 0 | AW23: =AV23*$AC23 -> 0 | AX23: =-AV23*$AD23 -> 0 | AY23: =AW23+AX23 -> 0 | AZ23: =AZ22+AY23 -> 0 | BB23: =AN23+AY23 -> 0 | BC23: =BC22+BB23 -> 0
A24: 46057 | B24: 53.96 | C24: 128.71 | D24: 2.3852854 | E24: 2.3831652 | F24: 2.3870508 | G24: 2.3812412 | H24: 128.59559 | I24: 128.83581 | J24: 128.41858 | K24: 0.00088926143 | L24: -0.0009769636 | M24: 0.0022667265 | N24: 0 | O24: 0 | P24: 53.96 | Q24: 128.71 | R24: 2.3852854 | S24: 2.3836499 | T24: 2.3870508 | U24: 2.3812412 | V24: 128.62175 | W24: 128.83581 | X24: 128.41858 | Y24: 0.00068588059 | Z24: -0.0009769636 | AA24: 0.0022667265 | AC24: =LN(B24/B23) -> 0.0080007869 | AD24: =LN(C24/C23) -> 0.008034678 | AH24: =IF(AA24<AG$1,1,0) -> 0 | AI24: =IF($AA24>AG$2,1,0) -> 1 | AJ24: =AK24 -> 0 | AK24: =IF(AH23,1,IF(AI23,0,AJ23)) -> 0 | AL24: =-AK24*$AC24 -> 0 | AM24: =AK24*$AD24 -> 0 | AN24: =AL24+AM24 -> 0 | AO24: =AO23+AN24 -> 0 | AS24: =IF($AA24>AR$1,1,0) -> 0 | AT24: =IF($AA24<AR$2,1,0) -> 0 | AU24: =AV23 -> 0 | AV24: =IF(AS23,1,IF(AT23,0,AU23)) -> 0 | AW24: =AV24*$AC24 -> 0 | AX24: =-AV24*$AD24 -> 0 | AY24: =AW24+AX24 -> 0 | AZ24: =AZ23+AY24 -> 0 | BB24: =AN24+AY24 -> 0 | BC24: =BC23+BB24 -> 0
A25: 46058 | B25: 53.29 | C25: 126.95 | D25: 2.3822481 | E25: 2.3831652 | F25: 2.3866396 | G25: 2.3827129 | H25: 126.99887 | I25: 127.20594 | J25: 126.89634 | K25: -0.00038490705 | L25: -0.0020140012 | M25: 0.00042274807 | N25: 0 | O25: 0 | P25: 53.29 | Q25: 126.95 | R25: 2.3822481 | S25: 2.3836499 | T25: 2.3866396 | U25: 2.3827129 | V25: 127.02471 | W25: 127.20594 | X25: 126.89634 | Y25: -0.00058828789 | Z25: -0.0020140012 | AA25: 0.00042274807 | AC25: =LN(B25/B24) -> -0.012494335 | AD25: =LN(C25/C24) -> -0.013768504 | AH25: =IF(AA25<AG$1,1,0) -> 0 | AI25: =IF($AA25>AG$2,1,0) -> 1 | AJ25: =AK25 -> 0 | AK25: =IF(AH24,1,IF(AI24,0,AJ24)) -> 0 | AL25: =-AK25*$AC25 -> 0 | AM25: =AK25*$AD25 -> 0 | AN25: =AL25+AM25 -> 0 | AO25: =AO24+AN25 -> 0 | AS25: =IF($AA25>AR$1,1,0) -> 0 | AT25: =IF($AA25<AR$2,1,0) -> 0 | AU25: =AV24 -> 0 | AV25: =IF(AS24,1,IF(AT24,0,AU24)) -> 0 | AW25: =AV25*$AC25 -> 0 | AX25: =-AV25*$AD25 -> 0 | AY25: =AW25+AX25 -> 0 | AZ25: =AZ24+AY25 -> 0 | BB25: =AN25+AY25 -> 0 | BC25: =BC24+BB25 -> 0
A26: 46059 | B26: 54.26 | C26: 129.64 | D26: 2.389237 | E26: 2.3831652 | F26: 2.3867655 | G26: 2.3842946 | H26: 129.31054 | I26: 129.49907 | J26: 129.286 | K26: 0.0025445522 | L26: 0.0010877078 | M26: 0.0027343626 | N26: 0 | O26: 0 | P26: 54.26 | Q26: 129.64 | R26: 2.389237 | S26: 2.3836499 | T26: 2.3867655 | U26: 2.3842946 | V26: 129.33685 | W26: 129.49907 | X26: 129.286 | Y26: 0.0023411713 | Z26: 0.0010877078 | AA26: 0.0027343626 | AC26: =LN(B26/B25) -> 0.018038611 | AD26: =LN(C26/C25) -> 0.02096807 | AH26: =IF(AA26<AG$1,1,0) -> 0 | AI26: =IF($AA26>AG$2,1,0) -> 1 | AJ26: =AK26 -> 0 | AK26: =IF(AH25,1,IF(AI25,0,AJ25)) -> 0 | AL26: =-AK26*$AC26 -> 0 | AM26: =AK26*$AD26 -> 0 | AN26: =AL26+AM26 -> 0 | AO26: =AO25+AN26 -> 0 | AS26: =IF($AA26>AR$1,1,0) -> 0 | AT26: =IF($AA26<AR$2,1,0) -> 0 | AU26: =AV25 -> 0 | AV26: =IF(AS25,1,IF(AT25,0,AU25)) -> 0 | AW26: =AV26*$AC26 -> 0 | AX26: =-AV26*$AD26 -> 0 | AY26: =AW26+AX26 -> 0 | AZ26: =AZ25+AY26 -> 0 | BB26: =AN26+AY26 -> 0 | BC26: =BC25+BB26 -> 0
A27: 46062 | B27: 53.94 | C27: 129.17 | D27: 2.3946978 | E27: 2.3831652 | F27: 2.3875347 | G27: 2.3859961 | H27: 128.54793 | I27: 128.74213 | J27: 128.60885 | K27: 0.0048275296 | L27: 0.0033179403 | M27: 0.0043537341 | N27: 0 | O27: 0 | P27: 53.94 | Q27: 129.17 | R27: 2.3946978 | S27: 2.3836499 | T27: 2.3875347 | U27: 2.3859961 | V27: 128.57408 | W27: 128.74213 | X27: 128.60885 | Y27: 0.0046241488 | Z27: 0.0033179403 | AA27: 0.0043537341 | AC27: =LN(B27/B26) -> -0.0059149895 | AD27: =LN(C27/C26) -> -0.003632012 | AH27: =IF(AA27<AG$1,1,0) -> 0 | AI27: =IF($AA27>AG$2,1,0) -> 1 | AJ27: =AK27 -> 0 | AK27: =IF(AH26,1,IF(AI26,0,AJ26)) -> 0 | AL27: =-AK27*$AC27 -> 0 | AM27: =AK27*$AD27 -> 0 | AN27: =AL27+AM27 -> 0 | AO27: =AO26+AN27 -> 0 | AS27: =IF($AA27>AR$1,1,0) -> 1 | AT27: =IF($AA27<AR$2,1,0) -> 0 | AU27: =AV26 -> 0 | AV27: =IF(AS26,1,IF(AT26,0,AU26)) -> 0 | AW27: =AV27*$AC27 -> 0 | AX27: =-AV27*$AD27 -> 0 | AY27: =AW27+AX27 -> 0 | AZ27: =AZ26+AY27 -> 0 | BB27: =AN27+AY27 -> 0 | BC27: =BC26+BB27 -> 0
A28: 46063 | B28: 53.55 | C28: 127.7 | D28: 2.3846872 | E28: 2.3831652 | F28: 2.3867204 | G28: 2.3867009 | H28: 127.6185 | I28: 127.85248 | J28: 127.77009 | K28: 0.00063844725 | L28: -0.0011933519 | M28: -0.00054872845 | N28: 0 | O28: 0 | P28: 53.55 | Q28: 127.7 | R28: 2.3846872 | S28: 2.3836499 | T28: 2.3867204 | U28: 2.3867009 | V28: 127.64445 | W28: 127.85248 | X28: 127.77009 | Y28: 0.00043506641 | Z28: -0.0011933519 | AA28: -0.00054872845 | AC28: =LN(B28/B27) -> -0.0072565208 | AD28: =LN(C28/C27) -> -0.011445603 | AH28: =IF(AA28<AG$1,1,0) -> 0 | AI28: =IF($AA28>AG$2,1,0) -> 1 | AJ28: =AK28 -> 0 | AK28: =IF(AH27,1,IF(AI27,0,AJ27)) -> 0 | AL28: =-AK28*$AC28 -> 0 | AM28: =AK28*$AD28 -> 0 | AN28: =AL28+AM28 -> 0 | AO28: =AO27+AN28 -> 0 | AS28: =IF($AA28>AR$1,1,0) -> 0 | AT28: =IF($AA28<AR$2,1,0) -> 1 | AU28: =AV27 -> 0 | AV28: =IF(AS27,1,IF(AT27,0,AU27)) -> 1 | AW28: =AV28*$AC28 -> -0.0072565208 | AX28: =-AV28*$AD28 -> 0.011445603 | AY28: =AW28+AX28 -> 0.0041890824 | AZ28: =AZ27+AY28 -> 0.0041890824 | BB28: =AN28+AY28 -> 0.0041890824 | BC28: =BC27+BB28 -> 0.0041890824
A29: 46064 | B29: 52.74 | C29: 125.66 | D29: 2.3826318 | E29: 2.3831652 | F29: 2.3858252 | G29: 2.3867471 | H29: 125.68813 | I29: 125.87563 | J29: 125.87461 | K29: -0.00022385284 | L29: -0.0017145316 | M29: -0.0017063706 | N29: 0 | O29: 0 | P29: 52.74 | Q29: 125.66 | R29: 2.3826318 | S29: 2.3836499 | T29: 2.3858252 | U29: 2.3867471 | V29: 125.7137 | W29: 125.87563 | X29: 125.87461 | Y29: -0.00042723368 | Z29: -0.0017145316 | AA29: -0.0017063706 | AC29: =LN(B29/B28) -> -0.015241616 | AD29: =LN(C29/C28) -> -0.016103916 | AH29: =IF(AA29<AG$1,1,0) -> 0 | AI29: =IF($AA29>AG$2,1,0) -> 1 | AJ29: =AK29 -> 0 | AK29: =IF(AH28,1,IF(AI28,0,AJ28)) -> 0 | AL29: =-AK29*$AC29 -> 0 | AM29: =AK29*$AD29 -> 0 | AN29: =AL29+AM29 -> 0 | AO29: =AO28+AN29 -> 0 | AS29: =IF($AA29>AR$1,1,0) -> 0 | AT29: =IF($AA29<AR$2,1,0) -> 1 | AU29: =AV28 -> 1 | AV29: =IF(AS28,1,IF(AT28,0,AU28)) -> 0 | AW29: =AV29*$AC29 -> 0 | AX29: =-AV29*$AD29 -> 0 | AY29: =AW29+AX29 -> 0 | AZ29: =AZ28+AY29 -> 0.0041890824 | BB29: =AN29+AY29 -> 0 | BC29: =BC28+BB29 -> 0.0041890824
A30: 46065 | B30: 51.69 | C30: 123.32 | D30: 2.3857613 | E30: 2.3831652 | F30: 2.3858953 | G30: 2.3869308 | H30: 123.18581 | I30: 123.32331 | J30: 123.37096 | K30: 0.0010887449 | L30: -2.6807416e-05 | M30: -0.00041313487 | N30: 0 | O30: 0 | P30: 51.69 | Q30: 123.32 | R30: 2.3857613 | S30: 2.3836499 | T30: 2.3858953 | U30: 2.3869308 | V30: 123.21087 | W30: 123.32331 | X30: 123.37096 | Y30: 0.00088536408 | Z30: -2.6807416e-05 | AA30: -0.00041313487 | AC30: =LN(B30/B29) -> -0.020109842 | AD30: =LN(C30/C29) -> -0.018797244 | AH30: =IF(AA30<AG$1,1,0) -> 0 | AI30: =IF($AA30>AG$2,1,0) -> 1 | AJ30: =AK30 -> 0 | AK30: =IF(AH29,1,IF(AI29,0,AJ29)) -> 0 | AL30: =-AK30*$AC30 -> 0 | AM30: =AK30*$AD30 -> 0 | AN30: =AL30+AM30 -> 0 | AO30: =AO29+AN30 -> 0 | AS30: =IF($AA30>AR$1,1,0) -> 0 | AT30: =IF($AA30<AR$2,1,0) -> 1 | AU30: =AV29 -> 0 | AV30: =IF(AS29,1,IF(AT29,0,AU29)) -> 0 | AW30: =AV30*$AC30 -> 0 | AX30: =-AV30*$AD30 -> 0 | AY30: =AW30+AX30 -> 0 | AZ30: =AZ29+AY30 -> 0.0041890824 | BB30: =AN30+AY30 -> 0 | BC30: =BC29+BB30 -> 0.0041890824
A31: 46066 | B31: 51.65 | C31: 123.83 | D31: 2.3974831 | E31: 2.3831652 | F31: 2.386684 | G31: 2.3874745 | H31: 123.09048 | I31: 123.23149 | J31: 123.28498 | K31: 0.0059899428 | L31: 0.0048450267 | M31: 0.0044110894 | N31: 0 | O31: 0 | P31: 51.65 | Q31: 123.83 | R31: 2.3974831 | S31: 2.3836499 | T31: 2.386684 | U31: 2.3874745 | V31: 123.11552 | W31: 123.23149 | X31: 123.28498 | Y31: 0.0057865619 | Z31: 0.0048450267 | AA31: 0.0044110894 | AC31: =LN(B31/B30) -> -0.00077414364 | AD31: =LN(C31/C30) -> 0.0041270542 | AH31: =IF(AA31<AG$1,1,0) -> 0 | AI31: =IF($AA31>AG$2,1,0) -> 1 | AJ31: =AK31 -> 0 | AK31: =IF(AH30,1,IF(AI30,0,AJ30)) -> 0 | AL31: =-AK31*$AC31 -> 0 | AM31: =AK31*$AD31 -> 0 | AN31: =AL31+AM31 -> 0 | AO31: =AO30+AN31 -> 0 | AS31: =IF($AA31>AR$1,1,0) -> 1 | AT31: =IF($AA31<AR$2,1,0) -> 0 | AU31: =AV30 -> 0 | AV31: =IF(AS30,1,IF(AT30,0,AU30)) -> 0 | AW31: =AV31*$AC31 -> 0 | AX31: =-AV31*$AD31 -> 0 | AY31: =AW31+AX31 -> 0 | AZ31: =AZ30+AY31 -> 0.0041890824 | BB31: =AN31+AY31 -> 0 | BC31: =BC30+BB31 -> 0.0041890824
A32: 46070 | B32: 52.2 | C32: 124.84 | D32: 2.3915709 | E32: 2.3831652 | F32: 2.3878807 | G32: 2.3878025 | H32: 124.40122 | I32: 124.58491 | J32: 124.62617 | K32: 0.0035209036 | L32: 0.0020454639 | M32: 0.0017143193 | N32: 0 | O32: 0 | P32: 52.2 | Q32: 124.84 | R32: 2.3915709 | S32: 2.3836499 | T32: 2.3878807 | U32: 2.3878025 | V32: 124.42653 | W32: 124.58491 | X32: 124.62617 | Y32: 0.0033175228 | Z32: 0.0020454639 | AA32: 0.0017143193 | AC32: =LN(B32/B31) -> 0.010592299 | AD32: =LN(C32/C31) -> 0.0081232602 | AH32: =IF(AA32<AG$1,1,0) -> 0 | AI32: =IF($AA32>AG$2,1,0) -> 1 | AJ32: =AK32 -> 0 | AK32: =IF(AH31,1,IF(AI31,0,AJ31)) -> 0 | AL32: =-AK32*$AC32 -> 0 | AM32: =AK32*$AD32 -> 0 | AN32: =AL32+AM32 -> 0 | AO32: =AO31+AN32 -> 0 | AS32: =IF($AA32>AR$1,1,0) -> 0 | AT32: =IF($AA32<AR$2,1,0) -> 0 | AU32: =AV31 -> 0 | AV32: =IF(AS31,1,IF(AT31,0,AU31)) -> 1 | AW32: =AV32*$AC32 -> 0.010592299 | AX32: =-AV32*$AD32 -> -0.0081232602 | AY32: =AW32+AX32 -> 0.0024690391 | AZ32: =AZ31+AY32 -> 0.0066581215 | BB32: =AN32+AY32 -> 0.0024690391 | BC32: =BC31+BB32 -> 0.0066581215
A33: 46071 | B33: 52.59 | C33: 125.8 | D33: 2.3920898 | E33: 2.3831652 | F33: 2.3885692 | G33: 2.388093 | H33: 125.33066 | I33: 125.57865 | J33: 125.57453 | K33: 0.0037378378 | L33: 0.0017611185 | M33: 0.0017938822 | N33: 0 | O33: 0 | P33: 52.59 | Q33: 125.8 | R33: 2.3920898 | S33: 2.3836499 | T33: 2.3885692 | U33: 2.388093 | V33: 125.35615 | W33: 125.57865 | X33: 125.57453 | Y33: 0.0035344569 | Z33: 0.0017611185 | AA33: 0.0017938822 | AC33: =LN(B33/B32) -> 0.0074434927 | AD33: =LN(C33/C32) -> 0.0076604269 | AH33: =IF(AA33<AG$1,1,0) -> 0 | AI33: =IF($AA33>AG$2,1,0) -> 1 | AJ33: =AK33 -> 0 | AK33: =IF(AH32,1,IF(AI32,0,AJ32)) -> 0 | AL33: =-AK33*$AC33 -> 0 | AM33: =AK33*$AD33 -> 0 | AN33: =AL33+AM33 -> 0 | AO33: =AO32+AN33 -> 0 | AS33: =IF($AA33>AR$1,1,0) -> 0 | AT33: =IF($AA33<AR$2,1,0) -> 0 | AU33: =AV32 -> 1 | AV33: =IF(AS32,1,IF(AT32,0,AU32)) -> 0 | AW33: =AV33*$AC33 -> 0 | AX33: =-AV33*$AD33 -> 0 | AY33: =AW33+AX33 -> 0 | AZ33: =AZ32+AY33 -> 0.0066581215 | BB33: =AN33+AY33 -> 0 | BC33: =BC32+BB33 -> 0.0066581215
A34: 46072 | B34: 52.15 | C34: 124.76 | D34: 2.3923298 | E34: 2.3831652 | F34: 2.3892737 | G34: 2.3881622 | H34: 124.28207 | I34: 124.56389 | J34: 124.53905 | K34: 0.0038381914 | L34: 0.0015731747 | M34: 0.0017725506 | N34: 0 | O34: 0 | P34: 52.15 | Q34: 124.76 | R34: 2.3923298 | S34: 2.3836499 | T34: 2.3892737 | U34: 2.3881622 | V34: 124.30734 | W34: 124.56389 | X34: 124.53905 | Y34: 0.0036348106 | Z34: 0.0015731747 | AA34: 0.0017725506 | AC34: =LN(B34/B33) -> -0.0084018062 | AD34: =LN(C34/C33) -> -0.0083014525 | AH34: =IF(AA34<AG$1,1,0) -> 0 | AI34: =IF($AA34>AG$2,1,0) -> 1 | AJ34: =AK34 -> 0 | AK34: =IF(AH33,1,IF(AI33,0,AJ33)) -> 0 | AL34: =-AK34*$AC34 -> 0 | AM34: =AK34*$AD34 -> 0 | AN34: =AL34+AM34 -> 0 | AO34: =AO33+AN34 -> 0 | AS34: =IF($AA34>AR$1,1,0) -> 0 | AT34: =IF($AA34<AR$2,1,0) -> 0 | AU34: =AV33 -> 0 | AV34: =IF(AS33,1,IF(AT33,0,AU33)) -> 1 | AW34: =AV34*$AC34 -> -0.0084018062 | AX34: =-AV34*$AD34 -> 0.0083014525 | AY34: =AW34+AX34 -> -0.00010035363 | AZ34: =AZ33+AY34 -> 0.0065577679 | BB34: =AN34+AY34 -> -0.00010035363 | BC34: =BC33+BB34 -> 0.0065577679
... A156: 46248 | B156: 58.16 | C156: 138.29 | D156: 2.377751 | E156: 2.3831652 | F156: 2.3735195 | G156: 2.3733094 | H156: 138.60489 | I156: 137.96839 | J156: 138.02432 | K156: -0.0022744226 | L156: 0.002328302 | M156: 0.0019230058 | N156: 0 | O156: 0 | P156: 58.16 | Q156: 138.29 | R156: 2.377751 | S156: 2.3836499 | T156: 2.3735195 | U156: 2.3733094 | V156: 138.63308 | W156: 137.96839 | X156: 138.02432 | Y156: -0.0024778035 | Z156: 0.002328302 | AA156: 0.0019230058 | AC156: =LN(B156/B155) -> -0.0017179183 | AD156: =LN(C156/C155) -> -0.0015895957 | AH156: =IF(AA156<AG$1,1,0) -> 0 | AI156: =IF($AA156>AG$2,1,0) -> 1 | AJ156: =AK156 -> 0 | AK156: =IF(AH155,1,IF(AI155,0,AJ155)) -> 0 | AL156: =-AK156*$AC156 -> 0 | AM156: =AK156*$AD156 -> 0 | AN156: =AL156+AM156 -> 0 | AO156: =AO155+AN156 -> 0.019435292 | AS156: =IF($AA156>AR$1,1,0) -> 0 | AT156: =IF($AA156<AR$2,1,0) -> 0 | AU156: =AV155 -> 0 | AV156: =IF(AS155,1,IF(AT155,0,AU155)) -> 0 | AW156: =AV156*$AC156 -> 0 | AX156: =-AV156*$AD156 -> 0 | AY156: =AW156+AX156 -> 0 | AZ156: =AZ155+AY156 -> 0.029060433 | BB156: =AN156+AY156 -> 0 | BC156: =BC155+BB156 -> 0.048495725

Sheet XLK_IYW
A1: date | B1: XLK | C1: IYW | D1: IYW/XLK | E1: IYW/XLK avg | F1: IYW/XLK 10 dma | G1: IYW/XLK 20 dma | H1: XLK avg | I1: XLK 10 dma | J1: XLK 20 dma | K1: avg diff | L1: 10 dma diff | M1: 20 dma diff | N1: XLK div | O1: IYW div | P1: XLK* | Q1: IYW* | R1: IYW*/XLK* | S1: IYW*/XLK* avg | T1: IYW*/XLK* 10 dma | U1: IYW*/XLK* 20 dma | V1: XLK* avg | W1: XLK* 10 dma | X1: XLK* 20 dma | Y1: avg diff* | Z1: 10 dma diff* | AA1: 20 dma diff* | AC1: =_xlfn.CONCAT(B1," rtn") -> XLK rtn | AD1: =_xlfn.CONCAT(C1," rtn") -> IYW rtn | AF1: signal | AG1: -0.003 | AH1: under | AI1: over | AJ1: yday | AK1: position | AO1: =AO156 -> 0.025961979 | AQ1: signal | AR1: 0.002 | AS1: over | AT1: under | AU1: yday | AV1: position | AZ1: =AZ156 -> 0.042207549 | BC1: =BC156 -> 0.068169528
A2: 46024 | B2: 144.3 | C2: 199.89 | D2: 1.3852391 | E2: 1.35713 | N2: 0 | O2: 0 | P2: 144.3 | Q2: 199.89 | R2: 1.3852391 | S2: 1.3571528 | AG2: 0 | AR2: 0
A3: 46027 | B3: 144.62 | C3: 200.4 | D3: 1.3857005 | E3: 1.35713 | H3: 196.26813 | K3: 0.020833611 | N3: 0 | O3: 0 | P3: 144.62 | Q3: 200.4 | R3: 1.3857005 | S3: 1.3571528 | V3: 196.27144 | Y3: 0.020816748 | AC3: =LN(B3/B2) -> 0.002215147 | AD3: =LN(C3/C2) -> 0.002548154
A4: 46028 | B4: 146.65 | C4: 202.33 | D4: 1.3796795 | E4: 1.35713 | H4: 199.02311 | K4: 0.016479087 | N4: 0 | O4: 0 | P4: 146.65 | Q4: 202.33 | R4: 1.3796795 | S4: 1.3571528 | V4: 199.02646 | Y4: 0.016462223 | AC4: =LN(B4/B3) -> 0.013939183 | AD4: =LN(C4/C3) -> 0.0095846586
A5: 46029 | B5: 146.53 | C5: 202.65 | D5: 1.3829932 | E5: 1.35713 | H5: 198.86025 | K5: 0.018878022 | N5: 0 | O5: 0 | P5: 146.53 | Q5: 202.65 | R5: 1.3829932 | S5: 1.3571528 | V5: 198.86361 | Y5: 0.018861159 | AC5: =LN(B5/B4) -> -0.00081860977 | AD5: =LN(C5/C4) -> 0.0015803253
A6: 46030 | B6: 144.24 | C6: 199.78 | D6: 1.3850527 | E6: 1.35713 | H6: 195.75243 | K6: 0.020366036 | N6: 0 | O6: 0 | P6: 144.24 | Q6: 199.78 | R6: 1.3850527 | S6: 1.3571528 | V6: 195.75573 | Y6: 0.020349173 | AC6: =LN(B6/B5) -> -0.015751607 | AD6: =LN(C6/C5) -> -0.014263592
A7: 46031 | B7: 146.15 | C7: 201.75 | D7: 1.3804311 | E7: 1.35713 | H7: 198.34454 | K7: 0.01702367 | N7: 0 | O7: 0 | P7: 146.15 | Q7: 201.75 | R7: 1.3804311 | S7: 1.3571528 | V7: 198.34789 | Y7: 0.017006807 | AC7: =LN(B7/B6) -> 0.013154913 | AD7: =LN(C7/C6) -> 0.009812546
A8: 46034 | B8: 146.79 | C8: 202.42 | D8: 1.3789768 | E8: 1.35713 | H8: 199.21311 | K8: 0.015969607 | N8: 0 | O8: 0 | P8: 146.79 | Q8: 202.42 | R8: 1.3789768 | S8: 1.3571528 | V8: 199.21647 | Y8: 0.015952744 | AC8: =LN(B8/B7) -> 0.0043695024 | AD8: =LN(C8/C7) -> 0.0033154396
A9: 46035 | B9: 146.48 | C9: 201.9 | D9: 1.3783452 | E9: 1.35713 | H9: 198.7924 | K9: 0.015511479 | N9: 0 | O9: 0 | P9: 146.48 | Q9: 201.9 | R9: 1.3783452 | S9: 1.3571528 | V9: 198.79575 | Y9: 0.015494616 | AC9: =LN(B9/B8) -> -0.0021140936 | AD9: =LN(C9/C8) -> -0.0025722214 | AN9: =AVERAGE(AN22:AN200) -> 0.00019231095 | AY9: =AVERAGE(AY22:AY200) -> 0.00031264851 | BB9: =AVERAGE(BB22:BB200) -> 0.00050495947
A10: 46036 | B10: 144.7 | C10: 199.26 | D10: 1.377056 | E10: 1.35713 | H10: 196.37671 | K10: 0.014575725 | N10: 0 | O10: 0 | P10: 144.7 | Q10: 199.26 | R10: 1.377056 | S10: 1.3571528 | V10: 196.38002 | Y10: 0.014558862 | AC10: =LN(B10/B9) -> -0.012226267 | AD10: =LN(C10/C9) -> -0.013162021 | AN10: =STDEV(AN22:AN200) -> 0.0025799532 | AY10: =STDEV(AY22:AY200) -> 0.0026969952 | BB10: =STDEV(BB22:BB200) -> 0.0037160184
A11: 46037 | B11: 145.46 | C11: 199.9 | D11: 1.374261 | E11: 1.35713 | F11: 1.3807735 | H11: 197.40812 | K11: 0.012543961 | N11: 0 | O11: 0 | P11: 145.46 | Q11: 199.9 | R11: 1.374261 | S11: 1.3571528 | T11: 1.3807735 | V11: 197.41145 | Y11: 0.012527098 | AC11: =LN(B11/B10) -> 0.0052385011 | AD11: =LN(C11/C10) -> 0.0032067369 | AN11: =SQRT(252)*AN9/AN10 -> 1.1832935 | AY11: =SQRT(252)*AY9/AY10 -> 1.8402485 | BB11: =SQRT(252)*BB9/BB10 -> 2.157143
A12: 46038 | B12: 145.62 | C12: 199.89 | D12: 1.3726823 | E12: 1.35713 | F12: 1.3795178 | H12: 197.62526 | I12: 201.06824 | K12: 0.011394581 | L12: -0.0058771179 | N12: 0 | O12: 0 | P12: 145.62 | Q12: 199.89 | R12: 1.3726823 | S12: 1.3571528 | T12: 1.3795178 | V12: 197.6286 | W12: 201.06824 | Y12: 0.011377717 | Z12: -0.0058771179 | AC12: =LN(B12/B11) -> 0.0010993542 | AD12: =LN(C12/C11) -> -5.0026264e-05
A13: 46042 | B13: 141.84 | C13: 194.71 | D13: 1.3727439 | E13: 1.35713 | F13: 1.3782222 | H13: 192.49531 | I13: 195.67081 | K13: 0.011439465 | L13: -0.0049224195 | N13: 0 | O13: 0 | P13: 141.84 | Q13: 194.71 | R13: 1.3727439 | S13: 1.3571528 | T13: 1.3782222 | V13: 192.49856 | W13: 195.67081 | Y13: 0.011422601 | Z13: -0.0049224195 | AC13: =LN(B13/B12) -> -0.026300827 | AD13: =LN(C13/C12) -> -0.026255943
A14: 46043 | B14: 143.81 | C14: 197.17 | D14: 1.3710451 | E14: 1.35713 | F14: 1.3773587 | H14: 195.16886 | I14: 198.20213 | K14: 0.010201171 | L14: -0.0052210653 | N14: 0 | O14: 0 | P14: 143.81 | Q14: 197.17 | R14: 1.3710451 | S14: 1.3571528 | T14: 1.3773587 | V14: 195.17215 | W14: 198.20213 | Y14: 0.010184308 | Z14: -0.0052210653 | AC14: =LN(B14/B13) -> 0.013793322 | AD14: =LN(C14/C13) -> 0.012555029
A15: 46044 | B15: 144.88 | C15: 198.93 | D15: 1.3730674 | E15: 1.35713 | F15: 1.3763661 | H15: 196.62099 | I15: 199.55173 | K15: 0.011675045 | L15: -0.0031205085 | N15: 0 | O15: 0 | P15: 144.88 | Q15: 198.93 | R15: 1.3730674 | S15: 1.3571528 | T15: 1.3763661 | V15: 196.6243 | W15: 199.55173 | Y15: 0.011658182 | Z15: -0.0031205085 | AC15: =LN(B15/B14) -> 0.0074128297 | AD15: =LN(C15/C14) -> 0.0088867033
A16: 46045 | B16: 145.09 | C16: 199.72 | D16: 1.3765249 | E16: 1.35713 | F16: 1.3755134 | H16: 196.90599 | I16: 199.69696 | K16: 0.01419 | L16: 0.00011535268 | N16: 0 | O16: 0 | P16: 145.09 | Q16: 199.72 | R16: 1.3765249 | S16: 1.3571528 | T16: 1.3755134 | V16: 196.90931 | W16: 199.69696 | Y16: 0.014173137 | Z16: 0.00011535268 | AC16: =LN(B16/B15) -> 0.001448426 | AD16: =LN(C16/C15) -> 0.0039633816
A17: 46048 | B17: 146.08 | C17: 201.24 | D17: 1.3776013 | E17: 1.35713 | F17: 1.3752304 | H17: 198.24954 | I17: 200.93499 | K17: 0.014971663 | L17: 0.0015167936 | N17: 0 | O17: 0 | P17: 146.08 | Q17: 201.24 | R17: 1.3776013 | S17: 1.3571528 | T17: 1.3752304 | V17: 198.25289 | W17: 200.93499 | Y17: 0.0149548 | Z17: 0.0015167936 | AC17: =LN(B17/B16) -> 0.0068001773 | AD17: =LN(C17/C16) -> 0.00758184
A18: 46049 | B18: 148.05 | C18: 203.7 | D18: 1.3758865 | E18: 1.35713 | F18: 1.3749214 | H18: 200.92309 | I18: 203.60286 | K18: 0.013726123 | L18: 0.00047699779 | N18: 0 | O18: 0 | P18: 148.05 | Q18: 203.7 | R18: 1.3758865 | S18: 1.3571528 | T18: 1.3749214 | V18: 200.92648 | W18: 203.60286 | Y18: 0.01370926 | Z18: 0.00047699779 | AC18: =LN(B18/B17) -> 0.013395638 | AD18: =LN(C18/C17) -> 0.012150098
A19: 46050 | B19: 149.23 | C19: 204.72 | D19: 1.3718421 | E19: 1.35713 | F19: 1.3742711 | H19: 202.5245 | I19: 205.17951 | K19: 0.010782306 | L19: -0.0022420863 | N19: 0 | O19: 0 | P19: 149.23 | Q19: 204.72 | R19: 1.3718421 | S19: 1.3571528 | T19: 1.3742711 | V19: 202.52792 | W19: 205.17951 | Y19: 0.010765443 | Z19: -0.0022420863 | AC19: =LN(B19/B18) -> 0.0079386854 | AD19: =LN(C19/C18) -> 0.0049948686
